<?xml version="1.0" ?>
<sdf version="1.8">
  <model name="cyberbrick_robot">
    <pose>0 0 0.05 0 0 0</pose>
    
    <!-- Chassis -->
    <link name="base_link">
      <inertial>
        <mass>0.5</mass>
        <inertia>
          <ixx>0.001</ixx><ixy>0</ixy><ixz>0</ixz>
          <iyy>0.001</iyy><iyz>0</iyz>
          <izz>0.001</izz>
        </inertia>
      </inertial>
      <collision name="collision">
        <geometry>
          <box><size>0.15 0.10 0.05</size></box>
        </geometry>
      </collision>
      <visual name="visual">
        <geometry>
          <box><size>0.15 0.10 0.05</size></box>
        </geometry>
        <material>
          <ambient>0.2 0.2 0.8 1</ambient>
          <diffuse>0.2 0.2 0.8 1</diffuse>
        </material>
      </visual>
    </link>

    <!-- Left Wheel -->
    <link name="left_wheel">
      <pose>0 0.06 -0.025 -1.5707 0 0</pose>
      <inertial>
        <mass>0.1</mass>
        <inertia>
          <ixx>0.0001</ixx><ixy>0</ixy><ixz>0</ixz>
          <iyy>0.0001</iyy><iyz>0</iyz>
          <izz>0.0001</izz>
        </inertia>
      </inertial>
      <collision name="collision">
        <geometry>
          <cylinder><radius>0.025</radius><length>0.02</length></cylinder>
        </geometry>
      </collision>
      <visual name="visual">
        <geometry>
          <cylinder><radius>0.025</radius><length>0.02</length></cylinder>
        </geometry>
        <material>
          <ambient>0.1 0.1 0.1 1</ambient>
          <diffuse>0.1 0.1 0.1 1</diffuse>
        </material>
      </visual>
    </link>

    <!-- Right Wheel -->
    <link name="right_wheel">
      <pose>0 -0.06 -0.025 -1.5707 0 0</pose>
      <inertial>
        <mass>0.1</mass>
        <inertia>
          <ixx>0.0001</ixx><ixy>0</ixy><ixz>0</ixz>
          <iyy>0.0001</iyy><iyz>0</iyz>
          <izz>0.0001</izz>
        </inertia>
      </inertial>
      <collision name="collision">
        <geometry>
          <cylinder><radius>0.025</radius><length>0.02</length></cylinder>
        </geometry>
      </collision>
      <visual name="visual">
        <geometry>
          <cylinder><radius>0.025</radius><length>0.02</length></cylinder>
        </geometry>
        <material>
          <ambient>0.1 0.1 0.1 1</ambient>
          <diffuse>0.1 0.1 0.1 1</diffuse>
        </material>
      </visual>
    </link>

    <!-- Caster Wheel -->
    <link name="caster">
      <pose>0.055 0 -0.0375 0 0 0</pose>
      <inertial>
        <mass>0.05</mass>
        <inertia>
          <ixx>0.00001</ixx><ixy>0</ixy><ixz>0</ixz>
          <iyy>0.00001</iyy><iyz>0</iyz>
          <izz>0.00001</izz>
        </inertia>
      </inertial>
      <collision name="collision">
        <geometry>
          <sphere><radius>0.0125</radius></sphere>
        </geometry>
      </collision>
      <visual name="visual">
        <geometry>
          <sphere><radius>0.0125</radius></sphere>
        </geometry>
        <material>
          <ambient>0.9 0.9 0.9 1</ambient>
          <diffuse>0.9 0.9 0.9 1</diffuse>
        </material>
      </visual>
    </link>

    <!-- Joints -->
    <joint name="left_wheel_joint" type="revolute">
      <parent>base_link</parent>
      <child>left_wheel</child>
      <axis>
        <xyz>0 0 1</xyz>
        <limit>
          <lower>-1e+16</lower>
          <upper>1e+16</upper>
        </limit>
      </axis>
    </joint>

    <joint name="right_wheel_joint" type="revolute">
      <parent>base_link</parent>
      <child>right_wheel</child>
      <axis>
        <xyz>0 0 1</xyz>
        <limit>
          <lower>-1e+16</lower>
          <upper>1e+16</upper>
        </limit>
      </axis>
    </joint>

    <joint name="caster_joint" type="ball">
      <parent>base_link</parent>
      <child>caster</child>
    </joint>

    <!-- Differential Drive Plugin -->
    <plugin filename="libignition-gazebo6-diff-drive-system.so" name="ignition::gazebo::systems::DiffDrive">
      <left_joint>left_wheel_joint</left_joint>
      <right_joint>right_wheel_joint</right_joint>
      <wheel_separation>0.12</wheel_separation>
      <wheel_radius>0.025</wheel_radius>
      <odom_publish_frequency>50</odom_publish_frequency>
      <cmd_vel_topic>/cmd_vel</cmd_vel_topic>
      <odom_topic>/odom</odom_topic>
    </plugin>

  </model>
</sdf>
